
Error: class uri 'gevent' invalid or not found: 

[Traceback (most recent call last):
  File "/Users/rahulpoddar/my-work/pro_resumev4/talent/resume_analyzer_api_v1/venv/lib/python3.9/site-packages/gunicorn/workers/ggevent.py", line 12, in <module>
    import gevent
ModuleNotFoundError: No module named 'gevent'

During handling of the above exception, another exception occurred:

Traceback (most recent call last):
  File "/Users/rahulpoddar/my-work/pro_resumev4/talent/resume_analyzer_api_v1/venv/lib/python3.9/site-packages/gunicorn/util.py", line 110, in load_class
    mod = importlib.import_module('.'.join(components))
  File "/Library/Developer/CommandLineTools/Library/Frameworks/Python3.framework/Versions/3.9/lib/python3.9/importlib/__init__.py", line 127, in import_module
    return _bootstrap._gcd_import(name[level:], package, level)
  File "<frozen importlib._bootstrap>", line 1030, in _gcd_import
  File "<frozen importlib._bootstrap>", line 1007, in _find_and_load
  File "<frozen importlib._bootstrap>", line 986, in _find_and_load_unlocked
  File "<frozen importlib._bootstrap>", line 680, in _load_unlocked
  File "<frozen importlib._bootstrap_external>", line 850, in exec_module
  File "<frozen importlib._bootstrap>", line 228, in _call_with_frames_removed
  File "/Users/rahulpoddar/my-work/pro_resumev4/talent/resume_analyzer_api_v1/venv/lib/python3.9/site-packages/gunicorn/workers/ggevent.py", line 14, in <module>
    raise RuntimeError("gevent worker requires gevent 1.4 or higher")
RuntimeError: gevent worker requires gevent 1.4 or higher
]

[2025-08-07 21:45:44 +0530] [24774] [INFO] Starting gunicorn 23.0.0
[2025-08-07 21:45:44 +0530] [24774] [ERROR] Connection in use: ('0.0.0.0', 5000)
[2025-08-07 21:45:44 +0530] [24774] [ERROR] connection to ('0.0.0.0', 5000) failed: [Errno 48] Address already in use
[2025-08-07 21:45:45 +0530] [24774] [ERROR] Connection in use: ('0.0.0.0', 5000)
[2025-08-07 21:45:45 +0530] [24774] [ERROR] connection to ('0.0.0.0', 5000) failed: [Errno 48] Address already in use
[2025-08-07 21:45:46 +0530] [24774] [ERROR] Connection in use: ('0.0.0.0', 5000)
[2025-08-07 21:45:46 +0530] [24774] [ERROR] connection to ('0.0.0.0', 5000) failed: [Errno 48] Address already in use
[2025-08-07 21:45:47 +0530] [24774] [ERROR] Connection in use: ('0.0.0.0', 5000)
[2025-08-07 21:45:47 +0530] [24774] [ERROR] connection to ('0.0.0.0', 5000) failed: [Errno 48] Address already in use
[2025-08-13 07:16:31 +0530] [20224] [INFO] Starting gunicorn 23.0.0
[2025-08-13 07:16:31 +0530] [20224] [INFO] Listening at: http://0.0.0.0:8000 (20224)
[2025-08-13 07:16:31 +0530] [20224] [INFO] Using worker: sync
[2025-08-13 07:16:31 +0530] [20224] [ERROR] Unhandled exception in main loop
Traceback (most recent call last):
  File "/Users/rahulpoddar/my-work/pro_resumev4/talent/resume_analyzer_api_v1/venv/lib/python3.9/site-packages/gunicorn/arbiter.py", line 201, in run
    self.manage_workers()
  File "/Users/rahulpoddar/my-work/pro_resumev4/talent/resume_analyzer_api_v1/venv/lib/python3.9/site-packages/gunicorn/arbiter.py", line 570, in manage_workers
    self.spawn_workers()
  File "/Users/rahulpoddar/my-work/pro_resumev4/talent/resume_analyzer_api_v1/venv/lib/python3.9/site-packages/gunicorn/arbiter.py", line 641, in spawn_workers
    self.spawn_worker()
  File "/Users/rahulpoddar/my-work/pro_resumev4/talent/resume_analyzer_api_v1/venv/lib/python3.9/site-packages/gunicorn/arbiter.py", line 588, in spawn_worker
    worker = self.worker_class(self.worker_age, self.pid, self.LISTENERS,
  File "/Users/rahulpoddar/my-work/pro_resumev4/talent/resume_analyzer_api_v1/venv/lib/python3.9/site-packages/gunicorn/workers/base.py", line 65, in __init__
    self.tmp = WorkerTmp(cfg)
  File "/Users/rahulpoddar/my-work/pro_resumev4/talent/resume_analyzer_api_v1/venv/lib/python3.9/site-packages/gunicorn/workers/workertmp.py", line 22, in __init__
    raise RuntimeError("%s doesn't exist. Can't create workertmp." % fdir)
RuntimeError: /dev/shm doesn't exist. Can't create workertmp.
[2025-08-13 07:18:34 +0530] [20275] [INFO] Starting gunicorn 23.0.0
[2025-08-13 07:18:34 +0530] [20275] [INFO] Listening at: http://0.0.0.0:8000 (20275)
[2025-08-13 07:18:34 +0530] [20275] [INFO] Using worker: sync
[2025-08-13 07:18:34 +0530] [20275] [ERROR] Unhandled exception in main loop
Traceback (most recent call last):
  File "/Users/rahulpoddar/my-work/pro_resumev4/talent/resume_analyzer_api_v1/venv/lib/python3.9/site-packages/gunicorn/arbiter.py", line 201, in run
    self.manage_workers()
  File "/Users/rahulpoddar/my-work/pro_resumev4/talent/resume_analyzer_api_v1/venv/lib/python3.9/site-packages/gunicorn/arbiter.py", line 570, in manage_workers
    self.spawn_workers()
  File "/Users/rahulpoddar/my-work/pro_resumev4/talent/resume_analyzer_api_v1/venv/lib/python3.9/site-packages/gunicorn/arbiter.py", line 641, in spawn_workers
    self.spawn_worker()
  File "/Users/rahulpoddar/my-work/pro_resumev4/talent/resume_analyzer_api_v1/venv/lib/python3.9/site-packages/gunicorn/arbiter.py", line 588, in spawn_worker
    worker = self.worker_class(self.worker_age, self.pid, self.LISTENERS,
  File "/Users/rahulpoddar/my-work/pro_resumev4/talent/resume_analyzer_api_v1/venv/lib/python3.9/site-packages/gunicorn/workers/base.py", line 65, in __init__
    self.tmp = WorkerTmp(cfg)
  File "/Users/rahulpoddar/my-work/pro_resumev4/talent/resume_analyzer_api_v1/venv/lib/python3.9/site-packages/gunicorn/workers/workertmp.py", line 22, in __init__
    raise RuntimeError("%s doesn't exist. Can't create workertmp." % fdir)
RuntimeError: /dev/shm doesn't exist. Can't create workertmp.
[2025-08-13 07:19:07 +0530] [20281] [INFO] Starting gunicorn 23.0.0
[2025-08-13 07:19:07 +0530] [20281] [INFO] Listening at: http://0.0.0.0:8000 (20281)
[2025-08-13 07:19:07 +0530] [20281] [INFO] Using worker: sync
[2025-08-13 07:19:07 +0530] [20281] [ERROR] Unhandled exception in main loop
Traceback (most recent call last):
  File "/Users/rahulpoddar/my-work/pro_resumev4/talent/resume_analyzer_api_v1/venv/lib/python3.9/site-packages/gunicorn/arbiter.py", line 201, in run
    self.manage_workers()
  File "/Users/rahulpoddar/my-work/pro_resumev4/talent/resume_analyzer_api_v1/venv/lib/python3.9/site-packages/gunicorn/arbiter.py", line 570, in manage_workers
    self.spawn_workers()
  File "/Users/rahulpoddar/my-work/pro_resumev4/talent/resume_analyzer_api_v1/venv/lib/python3.9/site-packages/gunicorn/arbiter.py", line 641, in spawn_workers
    self.spawn_worker()
  File "/Users/rahulpoddar/my-work/pro_resumev4/talent/resume_analyzer_api_v1/venv/lib/python3.9/site-packages/gunicorn/arbiter.py", line 588, in spawn_worker
    worker = self.worker_class(self.worker_age, self.pid, self.LISTENERS,
  File "/Users/rahulpoddar/my-work/pro_resumev4/talent/resume_analyzer_api_v1/venv/lib/python3.9/site-packages/gunicorn/workers/base.py", line 65, in __init__
    self.tmp = WorkerTmp(cfg)
  File "/Users/rahulpoddar/my-work/pro_resumev4/talent/resume_analyzer_api_v1/venv/lib/python3.9/site-packages/gunicorn/workers/workertmp.py", line 22, in __init__
    raise RuntimeError("%s doesn't exist. Can't create workertmp." % fdir)
RuntimeError: /dev/shm doesn't exist. Can't create workertmp.
